Workbook
Name Slicer_company_name: #N/A
Name Slicer_month: #N/A
Name Slicer_month1: #N/A
Name Slicer_sector_name: #N/A

Sheet final Dashboard

Sheet Dashboard

Sheet rough
A5: potfolio_value | B5: =SUM('stocks '!M2:M11) -> 944110
A7: volatility | B7: =_xlfn.STDEV.S(fact_daily_prices[[daily Rturn ]]) -> 0.012947054
A11: avg trading volume | B11: =AVERAGE(fact_daily_prices[volume]) -> 25414.797
E12: Total_volume
E13: 26228070 | F13: =GETPIVOTDATA("[Measures].[Sum of volume]",$E$12) -> 26228070
A15: Row Labels | B15: Sum of daily Rturn | E15: Portfolio_value
A16: Consumer Discretionary | B16: 0.26694648 | E16: 944110 | F16: =GETPIVOTDATA("[Measures].[Sum of current_value]",$E$15) -> 944110
A17: Energy | B17: 0.13489042
A18: Financials | B18: 0.15563123
A19: Healthcare | B19: 0.34711843 | E19: Total market_cap
A20: Information Technology | B20: 0.048864015 | E20: 270498000 | F20: =GETPIVOTDATA("[Measures].[Sum of market_cap]",$E$19) -> 270498000
A21: Grand Total | B21: 0.95345056
E22: Average of volatility
A23: Row Labels | B23: Sum of P&L AMT | E23: 0.012915536 | F23: =GETPIVOTDATA("[Measures].[Average of volatility]",$E$22) -> 0.012915536
A24: Morgan Williams | B24: 4763699.7
A25: Jamie Anderson | B25: 2766142.5
A26: Taylor Shah | B26: 2709253.4
A27: Alex Lee | B27: 1843059.3
A28: Drew Patel | B28: 1518155.7
A29: Jordan Clark | B29: 1407153.8
A30: Alex Harris | B30: 1157488.5
A31: Jordan Wilson | B31: 1048688.1
A32: Robin Lewis | B32: 591844.2
A33: Hayden Nguyen | B33: 298970.87
A34: Grand Total | B34: 18104456
A37: Row Labels | B37: Trader_name | C37: Sum of Transaction_value | D37: Sum of P&L AMT
A38: TRD000008 | B38: =VLOOKUP(A38,dim_trader[],2,FALSE) -> Morgan Williams | C38: 11482323 | D38: 1104382.1
A39: TRD000015 | B39: =VLOOKUP(A39,dim_trader[],2,FALSE) -> Jamie Anderson | C39: 5813848.7 | D39: 1072783.4
A40: TRD000001 | B40: =VLOOKUP(A40,dim_trader[],2,FALSE) -> Taylor Shah | C40: 11350882 | D40: 812763.42 | E40: =VLOOKUP(A40,fact_trades_pnl_kpi!D4:R242,12,FALSE) -> 0
A41: TRD000007 | B41: =VLOOKUP(A41,dim_trader[],2,FALSE) -> Alex Lee | C41: 4239869.5 | D41: 719053.73 | E41: =VLOOKUP(A41,fact_trades_pnl_kpi!D5:R243,12,FALSE) -> 200233.37
A42: TRD000022 | B42: =VLOOKUP(A42,dim_trader[],2,FALSE) -> Drew Patel | C42: 4677035.8 | D42: 495524.29 | E42: =VLOOKUP(A42,fact_trades_pnl_kpi!D6:R244,12,FALSE) -> 0
A43: TRD000005 | B43: =VLOOKUP(A43,dim_trader[],2,FALSE) -> Jordan Clark | C43: 8357063 | D43: 486380.77 | E43: =VLOOKUP(A43,fact_trades_pnl_kpi!D7:R245,12,FALSE) -> 495524.29
A44: TRD000010 | B44: =VLOOKUP(A44,dim_trader[],2,FALSE) -> Alex Harris | C44: 8293182.8 | D44: 442081.48 | E44: =VLOOKUP(A44,fact_trades_pnl_kpi!D8:R246,12,FALSE) -> 46873.344
A45: TRD000019 | B45: =VLOOKUP(A45,dim_trader[],2,FALSE) -> Jordan Wilson | C45: 7864371.4 | D45: 305323.12 | E45: =VLOOKUP(A45,fact_trades_pnl_kpi!D9:R247,12,FALSE) -> 199116.51
A46: TRD000009 | B46: =VLOOKUP(A46,dim_trader[],2,FALSE) -> Robin Lewis | C46: 4825759.5 | D46: 200233.37 | E46: =VLOOKUP(A46,fact_trades_pnl_kpi!D10:R248,12,FALSE) -> 0
A47: TRD000018 | B47: =VLOOKUP(A47,dim_trader[],2,FALSE) -> Hayden Nguyen | C47: 3579174 | D47: 199116.51 | E47: =VLOOKUP(A47,fact_trades_pnl_kpi!D11:R249,12,FALSE) -> 0
A48: TRD000013 | B48: =VLOOKUP(A48,dim_trader[],2,FALSE) -> Rowan Clark | C48: 2933939.8 | D48: 143319.52 | E48: =VLOOKUP(A48,fact_trades_pnl_kpi!D12:R250,12,FALSE) -> 0
A49: TRD000012 | B49: =VLOOKUP(A49,dim_trader[],2,FALSE) -> Reese Williams | C49: 11259012 | D49: 92491.447 | E49: =VLOOKUP(A49,fact_trades_pnl_kpi!D13:R251,12,FALSE) -> 442081.48
A50: TRD000024 | B50: =VLOOKUP(A50,dim_trader[],2,FALSE) -> Taylor Wilson | C50: 6795013.4 | D50: 81749.575 | E50: =VLOOKUP(A50,fact_trades_pnl_kpi!D14:R252,12,FALSE) -> 305323.12
A51: TRD000003 | B51: =VLOOKUP(A51,dim_trader[],2,FALSE) -> Avery Garcia | C51: 12054912 | D51: 60143.336 | E51: =VLOOKUP(A51,fact_trades_pnl_kpi!D15:R253,12,FALSE) -> 812763.42
...

Sheet Charts
A21: Row Labels | B21: Sum of daily Rturn
A22: Consumer Discretionary | B22: 0.26694648
A23: Energy | B23: 0.13489042
A24: Financials | B24: 0.15563123
A25: Healthcare | B25: 0.34711843
A26: Information Technology | B26: 0.048864015
A27: Grand Total | B27: 0.95345056
A35: Row Labels | B35: Sum of volume
A36: NASDAQ | B36: 12936870
A37: NSE | B37: 13291200
A38: Grand Total | B38: 26228070
A46: Row Labels | B46: Average of daily Rturn
A47: Amazon.com Inc. | B47: 0.0020693525
A48: Apple Inc. | B48: 0.00066645422
A49: HDFC Bank | B49: 0.0012064436
A50: Infosys | B50: 0.00050450909
A51: Microsoft Corp. | B51: -0.00086463331
A52: Pfizer Inc. | B52: 0.0026908405
A53: Reliance Industries | B53: 0.0010456622
A54: Tata Consultancy Services | B54: 7.2460807e-05
A55: Grand Total | B55: 0.00092388621
A58: Row Labels | B58: Sum of avg_vol
A59: Jan | B59: 4676322.6
A60: Feb | B60: 4066367.4
A61: Mar | B61: 4269685.8
A62: Apr | B62: 4473004.2
A63: May | B63: 4473004.2
A64: Jun | B64: 4269685.8
A65: Grand Total | B65: 26228070

Sheet company wise data
A1: DATE | B1: COMPANY_ID | C1: OPEN | D1: HIGH | E1: LOW | F1: CLOSE | G1: VOLUME | H1: DAILY RETURN | I1: daily volatity
A2: 45658 | B2: COMP001 | C2: 796.56 | D2: 800.79 | E2: 792.33 | F2: 800.53 | G2: 42106 | H2: =IFERROR((F2-F1)/F1,0) -> 0 | I2: =_xlfn.STDEV.S(H2:H130) -> 0.012621048
A3: 45659 | B3: COMP001 | C3: 805.97 | D3: 809.55 | E3: 802.39 | F3: 803.94 | G3: 9680 | H3: =(F3-F2)/F2 -> 0.004259678 | I3: =_xlfn.STDEV.S(H3:H131) -> 0.012670638
A4: 45660 | B4: COMP001 | C4: 809.42 | D4: 818.12 | E4: 800.72 | F4: 806.96 | G4: 36153 | H4: =(F4-F3)/F3 -> 0.0037564992 | I4: =_xlfn.STDEV.S(H4:H132) -> 0.012715307
A5: 45663 | B5: COMP001 | C5: 818.82 | D5: 831.19 | E5: 806.45 | F5: 817.5 | G5: 9120 | H5: =(F5-F4)/F4 -> 0.013061366 | I5: =_xlfn.STDEV.S(H5:H133) -> 0.012761704
A6: 45664 | B6: COMP001 | C6: 805.15 | D6: 813.57 | E6: 796.72 | F6: 811.73 | G6: 21445 | H6: =(F6-F5)/F5 -> -0.007058104 | I6: =_xlfn.STDEV.S(H6:H134) -> 0.01270778
A7: 45665 | B7: COMP001 | C7: 810.34 | D7: 817.79 | E7: 802.88 | F7: 806.57 | G7: 32065 | H7: =(F7-F6)/F6 -> -0.0063567935 | I7: =_xlfn.STDEV.S(H7:H135) -> 0.012696483
A8: 45666 | B8: COMP001 | C8: 804.7 | D8: 816.71 | E8: 792.7 | F8: 800.97 | G8: 46936 | H8: =(F8-F7)/F7 -> -0.0069429808 | I8: =_xlfn.STDEV.S(H8:H136) -> 0.012748421
A9: 45667 | B9: COMP001 | C9: 793.07 | D9: 795.72 | E9: 790.42 | F9: 791.89 | G9: 21932 | H9: =(F9-F8)/F8 -> -0.011336255 | I9: =_xlfn.STDEV.S(H9:H137) -> 0.012734074
A10: 45670 | B10: COMP001 | C10: 768.48 | D10: 780.24 | E10: 756.73 | F10: 766.43 | G10: 44016 | H10: =(F10-F9)/F9 -> -0.03215093 | I10: =_xlfn.STDEV.S(H10:H138) -> 0.012814217
A11: 45671 | B11: COMP001 | C11: 772.58 | D11: 780.18 | E11: 764.98 | F11: 775.85 | G11: 2154 | H11: =(F11-F10)/F10 -> 0.012290751 | I11: =_xlfn.STDEV.S(H11:H139) -> 0.012501243
A12: 45672 | B12: COMP001 | C12: 787.6 | D12: 797.49 | E12: 777.72 | F12: 784.06 | G12: 13183 | H12: =(F12-F11)/F11 -> 0.010581942 | I12: =_xlfn.STDEV.S(H12:H140) -> 0.012560739
A13: 45673 | B13: COMP001 | C13: 768.68 | D13: 782.43 | E13: 754.94 | F13: 769.33 | G13: 6539 | H13: =(F13-F12)/F12 -> -0.018786828 | I13: =_xlfn.STDEV.S(H13:H141) -> 0.012530675
A14: 45674 | B14: COMP001 | C14: 767.61 | D14: 779.13 | E14: 756.09 | F14: 765.38 | G14: 49354 | H14: =(F14-F13)/F13 -> -0.0051343377 | I14: =_xlfn.STDEV.S(H14:H142) -> 0.012487649
... A130: 45838 | B130: COMP001 | C130: 795.75 | D130: 806.56 | E130: 784.95 | F130: 799.87 | G130: 24793 | H130: =(F130-F129)/F129 -> 0.021976056 | I130: =_xlfn.STDEV.S(H130:H258) -> 0.012936386
A133: DATE | B133: COMPANY_ID | C133: OPEN | D133: HIGH | E133: LOW | F133: CLOSE | G133: VOLUME
A134: 45658 | B134: COMP002 | C134: 1156.78 | D134: 1172.33 | E134: 1141.24 | F134: 1161 | G134: 11589 | H134: =IFERROR((F134-F133)/F133,0) -> 0 | I134: =_xlfn.STDEV.S(H134:H262) -> 0.012960979
A135: 45659 | B135: COMP002 | C135: 1148.38 | D135: 1160.76 | E135: 1136.01 | F135: 1156.75 | G135: 14046 | H135: =IFERROR((F135-F134)/F134,0) -> -0.0036606374 | I135: =_xlfn.STDEV.S(H135:H263) -> 0.013011828
A136: 45660 | B136: COMP002 | C136: 1140.48 | D136: 1141.28 | E136: 1139.68 | F136: 1140.1 | G136: 5324 | H136: =IFERROR((F136-F135)/F135,0) -> -0.014393776 | I136: =_xlfn.STDEV.S(H136:H264) -> 0.013058038
A137: 45663 | B137: COMP002 | C137: 1148.73 | D137: 1161.2 | E137: 1136.27 | F137: 1138.82 | G137: 42427 | H137: =IFERROR((F137-F136)/F136,0) -> -0.0011227085 | I137: =_xlfn.STDEV.S(H137:H265) -> 0.012989667
A138: 45664 | B138: COMP002 | C138: 1162.43 | D138: 1183.74 | E138: 1141.12 | F138: 1161.22 | G138: 42605 | H138: =IFERROR((F138-F137)/F137,0) -> 0.019669482 | I138: =_xlfn.STDEV.S(H138:H266) -> 0.013313805
A139: 45665 | B139: COMP002 | C139: 1158.1 | D139: 1175 | E139: 1141.21 | F139: 1152.52 | G139: 48077 | H139: =IFERROR((F139-F138)/F138,0) -> -0.0074921204 | I139: =_xlfn.STDEV.S(H139:H267) -> 0.013236064
A140: 45666 | B140: COMP002 | C140: 1170.78 | D140: 1189.54 | E140: 1152.02 | F140: 1173.84 | G140: 1846 | H140: =IFERROR((F140-F139)/F139,0) -> 0.018498594 | I140: =_xlfn.STDEV.S(H140:H268) -> 0.013223421
A141: 45667 | B141: COMP002 | C141: 1178.64 | D141: 1190.56 | E141: 1166.73 | F141: 1177.96 | G141: 23700 | H141: =IFERROR((F141-F140)/F140,0) -> 0.003509848 | I141: =_xlfn.STDEV.S(H141:H269) -> 0.013161337
A142: 45670 | B142: COMP002 | C142: 1203.64 | D142: 1215.09 | E142: 1192.2 | F142: 1196.67 | G142: 43101 | H142: =IFERROR((F142-F141)/F141,0) -> 0.015883392 | I142: =_xlfn.STDEV.S(H142:H270) -> 0.013175621
A143: 45671 | B143: COMP002 | C143: 1206.4 | D143: 1217.33 | E143: 1195.47 | F143: 1200.26 | G143: 46587 | H143: =IFERROR((F143-F142)/F142,0) -> 0.0029999916 | I143: =_xlfn.STDEV.S(H143:H271) -> 0.013106056
A144: 45672 | B144: COMP002 | C144: 1194.77 | D144: 1199.03 | E144: 1190.5 | F144: 1193.24 | G144: 40001 | H144: =IFERROR((F144-F143)/F143,0) -> -0.0058487328 | I144: =_xlfn.STDEV.S(H144:H272) -> 0.013148693
A145: 45673 | B145: COMP002 | C145: 1226.72 | D145: 1237.14 | E145: 1216.3 | F145: 1218.43 | G145: 2917 | H145: =IFERROR((F145-F144)/F144,0) -> 0.02111059 | I145: =_xlfn.STDEV.S(H145:H273) -> 0.013157518
... A262: 45838 | B262: COMP002 | C262: 1217.63 | D262: 1226.76 | E262: 1208.5 | F262: 1225.8 | G262: 5806 | H262: =IFERROR((F262-F261)/F261,0) -> -0.015500763 | I262: =_xlfn.STDEV.S(H262:H390) -> 0.01370317
A264: DATE | B264: COMPANY_ID | C264: OPEN | D264: HIGH | E264: LOW | F264: CLOSE | G264: VOLUME
A265: 45658 | B265: COMP003 | C265: 1974.24 | D265: 1983.08 | E265: 1965.4 | F265: 1967.98 | G265: 45064 | H265: =IFERROR((F265-F264)/F264,0) -> 0 | I265: =_xlfn.STDEV.S(H265:H393) -> 0.013745344
A266: 45659 | B266: COMP003 | C266: 2030.8 | D266: 2047.32 | E266: 2014.27 | F266: 2034.15 | G266: 28570 | H266: =IFERROR((F266-F265)/F265,0) -> 0.033623309 | I266: =_xlfn.STDEV.S(H266:H394) -> 0.013798935
A267: 45660 | B267: COMP003 | C267: 2021.01 | D267: 2026.12 | E267: 2015.9 | F267: 2015.94 | G267: 12745 | H267: =IFERROR((F267-F266)/F266,0) -> -0.0089521422 | I267: =_xlfn.STDEV.S(H267:H395) -> 0.013546989
A268: 45663 | B268: COMP003 | C268: 1992.73 | D268: 2018.24 | E268: 1967.23 | F268: 2007.26 | G268: 15288 | H268: =IFERROR((F268-F267)/F267,0) -> -0.0043056837 | I268: =_xlfn.STDEV.S(H268:H396) -> 0.01351826
A269: 45664 | B269: COMP003 | C269: 1972.17 | D269: 1991.18 | E269: 1953.17 | F269: 1987.12 | G269: 4342 | H269: =IFERROR((F269-F268)/F268,0) -> -0.010033578 | I269: =_xlfn.STDEV.S(H269:H397) -> 0.013510166
A270: 45665 | B270: COMP003 | C270: 2005.09 | D270: 2034.91 | E270: 1975.28 | F270: 2003.07 | G270: 24411 | H270: =IFERROR((F270-F269)/F269,0) -> 0.0080266919 | I270: =_xlfn.STDEV.S(H270:H398) -> 0.013484425
A271: 45666 | B271: COMP003 | C271: 1999.94 | D271: 2032.18 | E271: 1967.71 | F271: 1998.6 | G271: 4093 | H271: =IFERROR((F271-F270)/F270,0) -> -0.0022315745 | I271: =_xlfn.STDEV.S(H271:H399) -> 0.013471666
A272: 45667 | B272: COMP003 | C272: 1960.4 | D272: 1980.14 | E272: 1940.66 | F272: 1974.95 | G272: 45413 | H272: =IFERROR((F272-F271)/F271,0) -> -0.011833283 | I272: =_xlfn.STDEV.S(H272:H400) -> 0.013546463
A273: 45670 | B273: COMP003 | C273: 1986.24 | D273: 1997.86 | E273: 1974.62 | F273: 1991.84 | G273: 40214 | H273: =IFERROR((F273-F272)/F272,0) -> 0.0085521152 | I273: =_xlfn.STDEV.S(H273:H401) -> 0.013495349
A274: 45671 | B274: COMP003 | C274: 2007.88 | D274: 2029.17 | E274: 1986.58 | F274: 2012.28 | G274: 49901 | H274: =IFERROR((F274-F273)/F273,0) -> 0.010261868 | I274: =_xlfn.STDEV.S(H274:H402) -> 0.013492783
...

Sheet volatitlity
A1: company | B1: company_name | C1: volatility
A2: COMP001 | B2: =VLOOKUP(A2,dim_company[#All],2,FALSE) -> TCS | C2: ='company wise data'!I920 -> 0.014179885
A3: COMP002 | B3: =VLOOKUP(A3,dim_company[#All],2,FALSE) -> INFY | C3: ='company wise data'!I789 -> 0.014068271
A4: COMP003 | B4: =VLOOKUP(A4,dim_company[#All],2,FALSE) -> HDFCBANK | C4: ='company wise data'!I265 -> 0.013745344
A5: COMP004 | B5: =VLOOKUP(A5,dim_company[#All],2,FALSE) -> RELIANCE | C5: ='company wise data'!I134 -> 0.012960979
A6: COMP005 | B6: =VLOOKUP(A6,dim_company[#All],2,FALSE) -> AAPL | C6: ='company wise data'!I2 -> 0.012621048
A7: COMP006 | B7: =VLOOKUP(A7,dim_company[#All],2,FALSE) -> MSFT | C7: ='company wise data'!I658 -> 0.012282011
A8: COMP007 | B8: =VLOOKUP(A8,dim_company[#All],2,FALSE) -> AMZN | C8: ='company wise data'!I396 -> 0.011843419
A9: COMP008 | B9: =VLOOKUP(A9,dim_company[#All],2,FALSE) -> PFE | C9: ='company wise data'!I527 -> 0.011623334

Sheet stocks 
A1: ticker | B1: company_name | C1: exchange | D1: sector | E1: currency | F1: share_price | G1: outstanding_shares | H1: market_cap | I1: quantity | J1: buy_price | K1: initial_value | L1: current_price | M1: current_value | N1: return_pct
A2: INFY | B2: Infosys Ltd | C2: NSE | D2: IT | E2: INR | F2: 1500 | G2: 31800 | H2: 477000 | I2: 51 | J2: 1362.55 | K2: 69490.048 | L2: 1500 | M2: 76500 | N2: 10.087706
A3: TCS | B3: Tata Consultancy Services | C3: NSE | D3: IT | E3: INR | F3: 3200 | G3: 36000 | H3: 1152000 | I3: 75 | J3: 2918.0183 | K3: 218851.37 | L3: 3200 | M3: 240000 | N3: 9.663466
A4: HDFC | B4: HDFC Bank | C4: NSE | D4: Financials | E4: INR | F4: 1450 | G4: 25000 | H4: 36250000 | I4: 14 | J4: 1395.8941 | K4: 19542.517 | L4: 1450 | M4: 20300 | N4: 3.8760768
A5: RELI | B5: Reliance Industries | C5: NSE | D5: Energy | E5: INR | F5: 2600 | G5: 64000 | H5: 166400000 | I5: 178 | J5: 2222.4858 | K5: 395602.47 | L5: 2600 | M5: 462800 | N5: 16.986124
A6: WIPRO | B6: Wipro Ltd | C6: NSE | D6: IT | E6: INR | F6: 400 | G6: 22000 | H6: 8800000 | I6: 102 | J6: 385.46356 | K6: 39317.283 | L6: 400 | M6: 40800 | N6: 3.7711572
A7: AAPL | B7: Apple Inc | C7: NASDAQ | D7: Technology | E7: USD | F7: 170 | G7: 16000 | H7: 27200000 | I7: 42 | J7: 145.1021 | K7: 6094.2881 | L7: 170 | M7: 7140 | N7: 17.158886
A8: MSFT | B8: Microsoft Corp | C8: NASDAQ | D8: Technology | E8: USD | F8: 370 | G8: 76000 | H8: 28120000 | I8: 142 | J8: 316.1934 | K8: 44899.463 | L8: 370 | M8: 52540 | N8: 17.016989
A9: AMZN | B9: Amazon.com Inc | C9: NASDAQ | D9: Consumer Discretionary | E9: USD | F9: 140 | G9: 10000 | H9: 1400000 | I9: 82 | J9: 133.08007 | K9: 10912.566 | L9: 140 | M9: 11480 | N9: 5.1998216
A10: GOOGL | B10: Alphabet Inc | C10: NASDAQ | D10: Communication Services | E10: USD | F10: 130 | G10: 30000 | H10: 39000 | I10: 93 | J10: 121.09456 | K10: 11261.794 | L10: 130 | M10: 12090 | N10: 7.3541177
A11: TSLA | B11: Tesla Inc | C11: NASDAQ | D11: Automotive | E11: USD | F11: 220 | G11: 30000 | H11: 660000 | I11: 93 | J11: 202.6487 | K11: 18846.329 | L11: 220 | M11: 20460 | N11: 8.5622579

Sheet fact_trades
A1: trade_id | B1: order_id | C1: trade_ts | D1: DAY | E1: company_id | F1: side | G1: quantity | H1: Transaction_value | I1: P&L AMT | J1: P&l text | K1: Total_qty | L1: price | M1: fees | N1: trader_id | O1: portfolio_id | P1: date | Q1: calendar_id | R1: trade_ts_imputed | S1: fees_imputed | T1: portfolio_id_imputed | U1: is_orphan_trade
A2: TR_SYN_0000001 | B2: ORD00044 | C2: 45713.019 | D2: Tuesday | E2: COMP005 | F2: BUY | G2: 827 | H2: =fact_trades[[#This Row],[quantity]]*fact_trades[[#This Row],[price]] -> 191582.82 | I2: =IF(fact_trades[[#This Row],[side]]="BUY",-fact_trades[[#This Row],[Transaction_value]],fact_trades[[#This Row],[Transaction_value]]) -> -191582.82 | J2: =IF(fact_trades[[#This Row],[P&L AMT]]<0,"LOSS","PROFIT") -> LOSS | K2: =IF(fact_trades[[#This Row],[side]]="BUY",fact_trades[[#This Row],[quantity]],-fact_trades[[#This Row],[quantity]]) -> 827 | L2: 231.66 | M2: 95.79 | N2: TRD000028 | O2: PF000009 | P2: 45786 | Q2: 129 | R2: FALSE | S2: FALSE | T2: FALSE | U2: FALSE
A3: TR_SYN_0000002 | B3: ORD00147 | C3: 45726.024 | D3: Monday | E3: COMP008 | F3: BUY | G3: 665 | H3: =fact_trades[[#This Row],[quantity]]*fact_trades[[#This Row],[price]] -> 731333.75 | I3: =IF(fact_trades[[#This Row],[side]]="BUY",-fact_trades[[#This Row],[Transaction_value]],fact_trades[[#This Row],[Transaction_value]]) -> -731333.75 | J3: =IF(fact_trades[[#This Row],[P&L AMT]]<0,"LOSS","PROFIT") -> LOSS | K3: =IF(fact_trades[[#This Row],[side]]="BUY",fact_trades[[#This Row],[quantity]],-fact_trades[[#This Row],[quantity]]) -> 665 | L3: 1099.75 | M3: 365.67 | N3: TRD000010 | O3: PF000004 | P3: 45681 | Q3: 24 | R3: FALSE | S3: FALSE | T3: FALSE | U3: FALSE
A4: TR_SYN_0000003 | B4: ORD00281 | C4: 45832.041 | D4: Tuesday | E4: COMP003 | F4: SELL | G4: 787 | H4: =fact_trades[[#This Row],[quantity]]*fact_trades[[#This Row],[price]] -> 1696897.9 | I4: =IF(fact_trades[[#This Row],[side]]="BUY",-fact_trades[[#This Row],[Transaction_value]],fact_trades[[#This Row],[Transaction_value]]) -> 1696897.9 | J4: =IF(fact_trades[[#This Row],[P&L AMT]]<0,"LOSS","PROFIT") -> PROFIT | K4: =IF(fact_trades[[#This Row],[side]]="BUY",fact_trades[[#This Row],[quantity]],-fact_trades[[#This Row],[quantity]]) -> -787 | L4: 2156.16 | M4: 848.45 | N4: TRD000012 | O4: PF000007 | P4: 45714 | Q4: 57 | R4: FALSE | S4: FALSE | T4: FALSE | U4: FALSE
A5: TR_SYN_0000004 | B5: ORD00014 | C5: 45687.04 | D5: Thursday | E5: COMP004 | F5: BUY | G5: 194 | H5: =fact_trades[[#This Row],[quantity]]*fact_trades[[#This Row],[price]] -> 117265.24 | I5: =IF(fact_trades[[#This Row],[side]]="BUY",-fact_trades[[#This Row],[Transaction_value]],fact_trades[[#This Row],[Transaction_value]]) -> -117265.24 | J5: =IF(fact_trades[[#This Row],[P&L AMT]]<0,"LOSS","PROFIT") -> LOSS | K5: =IF(fact_trades[[#This Row],[side]]="BUY",fact_trades[[#This Row],[quantity]],-fact_trades[[#This Row],[quantity]]) -> 194 | L5: 604.46 | M5: 58.63 | N5: TRD000016 | O5: PF000010 | P5: 45820 | Q5: 163 | R5: FALSE | S5: FALSE | T5: FALSE | U5: FALSE
A6: TR_SYN_0000005 | B6: ORD00023 | C6: 45782.032 | D6: Monday | E6: COMP008 | F6: BUY | G6: 331 | H6: =fact_trades[[#This Row],[quantity]]*fact_trades[[#This Row],[price]] -> 453440.21 | I6: =IF(fact_trades[[#This Row],[side]]="BUY",-fact_trades[[#This Row],[Transaction_value]],fact_trades[[#This Row],[Transaction_value]]) -> -453440.21 | J6: =IF(fact_trades[[#This Row],[P&L AMT]]<0,"LOSS","PROFIT") -> LOSS | K6: =IF(fact_trades[[#This Row],[side]]="BUY",fact_trades[[#This Row],[quantity]],-fact_trades[[#This Row],[quantity]]) -> 331 | L6: 1369.91 | M6: 226.72 | N6: TRD000017 | O6: PF000010 | P6: 45673 | Q6: 16 | R6: FALSE | S6: FALSE | T6: FALSE | U6: FALSE
A7: TR_SYN_0000006 | B7: ORD00390 | C7: 45749.022 | D7: Wednesday | E7: COMP005 | F7: BUY | G7: 330 | H7: =fact_trades[[#This Row],[quantity]]*fact_trades[[#This Row],[price]] -> 81236.1 | I7: =IF(fact_trades[[#This Row],[side]]="BUY",-fact_trades[[#This Row],[Transaction_value]],fact_trades[[#This Row],[Transaction_value]]) -> -81236.1 | J7: =IF(fact_trades[[#This Row],[P&L AMT]]<0,"LOSS","PROFIT") -> LOSS | K7: =IF(fact_trades[[#This Row],[side]]="BUY",fact_trades[[#This Row],[quantity]],-fact_trades[[#This Row],[quantity]]) -> 330 | L7: 246.17 | M7: 40.62 | N7: TRD000026 | O7: PF000007 | P7: 45762 | Q7: 105 | R7: FALSE | S7: FALSE | T7: FALSE | U7: FALSE
A8: TR_SYN_0000007 | B8: ORD00249 | C8: 45765.025 | D8: Friday | E8: COMP006 | F8: BUY | G8: 203 | H8: =fact_trades[[#This Row],[quantity]]*fact_trades[[#This Row],[price]] -> 49002.17 | I8: =IF(fact_trades[[#This Row],[side]]="BUY",-fact_trades[[#This Row],[Transaction_value]],fact_trades[[#This Row],[Transaction_value]]) -> -49002.17 | J8: =IF(fact_trades[[#This Row],[P&L AMT]]<0,"LOSS","PROFIT") -> LOSS | K8: =IF(fact_trades[[#This Row],[side]]="BUY",fact_trades[[#This Row],[quantity]],-fact_trades[[#This Row],[quantity]]) -> 203 | L8: 241.39 | M8: 24.5 | N8: TRD000020 | O8: PF000003 | P8: 45763 | Q8: 106 | R8: FALSE | S8: FALSE | T8: FALSE | U8: FALSE
A9: TR_SYN_0000008 | B9: ORD00476 | C9: 45835.022 | D9: Friday | E9: COMP001 | F9: BUY | G9: 323 | H9: =fact_trades[[#This Row],[quantity]]*fact_trades[[#This Row],[price]] -> 253435.49 | I9: =IF(fact_trades[[#This Row],[side]]="BUY",-fact_trades[[#This Row],[Transaction_value]],fact_trades[[#This Row],[Transaction_value]]) -> -253435.49 | J9: =IF(fact_trades[[#This Row],[P&L AMT]]<0,"LOSS","PROFIT") -> LOSS | K9: =IF(fact_trades[[#This Row],[side]]="BUY",fact_trades[[#This Row],[quantity]],-fact_trades[[#This Row],[quantity]]) -> 323 | L9: 784.63 | M9: 126.72 | N9: TRD000030 | O9: PF000002 | P9: 45720 | Q9: 63 | R9: FALSE | S9: FALSE | T9: FALSE | U9: FALSE
A10: TR_SYN_0000009 | B10: ORD00374 | C10: 45834.002 | D10: Thursday | E10: COMP005 | F10: SELL | G10: 857 | H10: =fact_trades[[#This Row],[quantity]]*fact_trades[[#This Row],[price]] -> 218954.93 | I10: =IF(fact_trades[[#This Row],[side]]="BUY",-fact_trades[[#This Row],[Transaction_value]],fact_trades[[#This Row],[Transaction_value]]) -> 218954.93 | J10: =IF(fact_trades[[#This Row],[P&L AMT]]<0,"LOSS","PROFIT") -> PROFIT | K10: =IF(fact_trades[[#This Row],[side]]="BUY",fact_trades[[#This Row],[quantity]],-fact_trades[[#This Row],[quantity]]) -> -857 | L10: 255.49 | M10: 109.48 | N10: TRD000027 | O10: PF000009 | P10: 45659 | Q10: 2 | R10: FALSE | S10: FALSE | T10: FALSE | U10: FALSE
A11: TR_SYN_0000010 | B11: ORD00377 | C11: 45803.001 | D11: Monday | E11: COMP007 | F11: BUY | G11: 764 | H11: =fact_trades[[#This Row],[quantity]]*fact_trades[[#This Row],[price]] -> 464764.12 | I11: =IF(fact_trades[[#This Row],[side]]="BUY",-fact_trades[[#This Row],[Transaction_value]],fact_trades[[#This Row],[Transaction_value]]) -> -464764.12 | J11: =IF(fact_trades[[#This Row],[P&L AMT]]<0,"LOSS","PROFIT") -> LOSS | K11: =IF(fact_trades[[#This Row],[side]]="BUY",fact_trades[[#This Row],[quantity]],-fact_trades[[#This Row],[quantity]]) -> 764 | L11: 608.33 | M11: 232.38 | N11: TRD000002 | O11: PF000007 | P11: 45734 | Q11: 77 | R11: FALSE | S11: FALSE | T11: FALSE | U11: FALSE
A12: TR_SYN_0000011 | B12: ORD00063 | C12: 45778.033 | D12: Thursday | E12: COMP002 | F12: BUY | G12: 151 | H12: =fact_trades[[#This Row],[quantity]]*fact_trades[[#This Row],[price]] -> 182574.1 | I12: =IF(fact_trades[[#This Row],[side]]="BUY",-fact_trades[[#This Row],[Transaction_value]],fact_trades[[#This Row],[Transaction_value]]) -> -182574.1 | J12: =IF(fact_trades[[#This Row],[P&L AMT]]<0,"LOSS","PROFIT") -> LOSS | K12: =IF(fact_trades[[#This Row],[side]]="BUY",fact_trades[[#This Row],[quantity]],-fact_trades[[#This Row],[quantity]]) -> 151 | L12: 1209.1 | M12: 91.29 | N12: TRD000002 | O12: PF000001 | P12: 45810 | Q12: 153 | R12: FALSE | S12: FALSE | T12: FALSE | U12: FALSE
A13: TR_SYN_0000012 | B13: ORD00369 | C13: 45768.039 | D13: Monday | E13: COMP001 | F13: BUY | G13: 52 | H13: =fact_trades[[#This Row],[quantity]]*fact_trades[[#This Row],[price]] -> 41509.52 | I13: =IF(fact_trades[[#This Row],[side]]="BUY",-fact_trades[[#This Row],[Transaction_value]],fact_trades[[#This Row],[Transaction_value]]) -> -41509.52 | J13: =IF(fact_trades[[#This Row],[P&L AMT]]<0,"LOSS","PROFIT") -> LOSS | K13: =IF(fact_trades[[#This Row],[side]]="BUY",fact_trades[[#This Row],[quantity]],-fact_trades[[#This Row],[quantity]]) -> 52 | L13: 798.26 | M13: 20.75 | N13: TRD000003 | O13: PF000003 | P13: 45765 | Q13: 108 | R13: FALSE | S13: FALSE | T13: FALSE | U13: FALSE
... A501: TR_SYN_0000500 | B501: ORD00463 | C501: 45765.04 | D501: Friday | E501: COMP005 | F501: BUY | G501: 902 | H501: =fact_trades[[#This Row],[quantity]]*fact_trades[[#This Row],[price]] -> 231119.46 | I501: =IF(fact_trades[[#This Row],[side]]="BUY",-fact_trades[[#This Row],[Transaction_value]],fact_trades[[#This Row],[Transaction_value]]) -> -231119.46 | J501: =IF(fact_trades[[#This Row],[P&L AMT]]<0,"LOSS","PROFIT") -> LOSS | K501: =IF(fact_trades[[#This Row],[side]]="BUY",fact_trades[[#This Row],[quantity]],-fact_trades[[#This Row],[quantity]]) -> 902 | L501: 256.23 | M501: 115.56 | N501: TRD000025 | O501: PF000006 | P501: 45779 | Q501: 122 | R501: FALSE | S501: FALSE | T501: FALSE | U501: FALSE
K503: {=SUM(fact_trades[Total_qty]*$L$501)} -> 2267891.7

Sheet fact_trades_pnl_kpi
A1: portfolio_id | B1: company_id | C1: sell_trade_id | D1: trader_id | E1: sell_date | F1: calendar_id | G1: sell_price | H1: quantity_sold | I1: gross_sell_amount | J1: gross_buy_amount | K1: allocated_buy_fees | L1: allocated_sell_fees | M1: total_fees_allocated | N1: avg_buy_price | O1: total_cost_basis | P1: realized_profit | Q1: return_pct | R1: win_flag
A2: PF000001 | B2: COMP001 | C2: TR_SYN_0000249 | D2: TRD000004 | E2: 2025-01-20 | F2: 20 | G2: 754.85 | H2: 121 | I2: 91336.85 | J2: 91453.01 | K2: 45.727143 | L2: 45.67 | M2: 91.397143 | N2: 756.18791 | O2: 91498.737 | P2: -207.55714 | Q2: -0.0022684154 | R2: 0
A3: PF000001 | B3: COMP001 | C3: TR_SYN_0000196 | D3: TRD000025 | E3: 2025-03-10 | F3: 69 | G3: 821.15 | H3: 472 | I3: 387582.8 | J3: 356742.32 | K3: 178.37365 | L3: 193.79 | M3: 372.16365 | N3: 756.18791 | O3: 356920.69 | P3: 30468.316 | Q3: 0.085364387 | R3: 1
A4: PF000001 | B4: COMP001 | C4: TR_SYN_0000163 | D4: TRD000007 | E4: 2025-06-24 | F4: 175 | G4: 814.88 | H4: 923 | I4: 752134.24 | J4: 701230.34 | K4: 350.61222 | L4: 376.07 | M4: 726.68222 | N4: 760.10937 | O4: 701580.95 | P4: 50177.218 | Q4: 0.071520211 | R4: 1
A5: PF000001 | B5: COMP002 | C5: TR_SYN_0000454 | D5: TRD000019 | E5: 2025-06-16 | F5: 167 | G5: 1317.94 | H5: 280 | I5: 369023.2 | J5: 323671.6 | K5: 161.83767 | L5: 184.51 | M5: 346.34767 | N5: 1156.548 | O5: 323833.44 | P5: 45005.252 | Q5: 0.13897655 | R5: 1
A6: PF000001 | B6: COMP002 | C6: TR_SYN_0000210 | D6: TRD000010 | E6: 2025-01-17 | F6: 17 | G6: 1336.02 | H6: 298 | I6: 398133.96 | J6: 344479.06 | K6: 172.24152 | L6: 199.07 | M6: 371.31152 | N6: 1156.548 | O6: 344651.3 | P6: 53283.588 | Q6: 0.15460144 | R6: 1
A7: PF000001 | B7: COMP002 | C7: TR_SYN_0000345 | D7: TRD000029 | E7: 2025-02-26 | F7: 57 | G7: 1185.76 | H7: 53 | I7: 62845.28 | J7: 61266.41 | K7: 30.63356 | L7: 31.42 | M7: 62.05356 | N7: 1156.548 | O7: 61297.044 | P7: 1516.8164 | Q7: 0.024745344 | R7: 1
A8: PF000001 | B8: COMP002 | C8: TR_SYN_0000358 | D8: TRD000014 | E8: 2025-03-31 | F8: 90 | G8: 1215.01 | H8: 783 | I8: 951352.83 | J8: 287767.37 | K8: 143.88724 | L8: 475.68 | M8: 619.56724 | N8: 367.70276 | O8: 287911.26 | P8: 662965.89 | Q8: 2.3026744 | R8: 1
A9: PF000001 | B9: COMP002 | C9: TR_SYN_0000489 | D9: TRD000027 | E9: 2025-02-07 | F9: 38 | G9: 1306.9 | H9: 867 | I9: 1133082.3 | J9: 0 | K9: 0 | L9: 566.54 | M9: 566.54 | N9: 0 | O9: 0 | P9: 1132515.8 | Q9: 0 | R9: 1
A10: PF000001 | B10: COMP003 | C10: TR_SYN_0000017 | D10: TRD000028 | E10: 2025-03-18 | F10: 77 | G10: 2239.99 | H10: 213 | I10: 477117.87 | J10: 443354.37 | K10: 221.68029 | L10: 238.56 | M10: 460.24029 | N10: 2082.5167 | O10: 443576.05 | P10: 33303.26 | Q10: 0.07507903 | R10: 1
A11: PF000001 | B11: COMP004 | C11: TR_SYN_0000216 | D11: TRD000003 | E11: 2025-02-27 | F11: 58 | G11: 608.29 | H11: 903 | I11: 549285.87 | J11: 0 | K11: 0 | L11: 274.64 | M11: 274.64 | N11: 0 | O11: 0 | P11: 549011.23 | Q11: 0 | R11: 1
A12: PF000001 | B12: COMP004 | C12: TR_SYN_0000396 | D12: TRD000001 | E12: 2025-05-22 | F12: 142 | G12: 630.6 | H12: 955 | I12: 602223 | J12: 0 | K12: 0 | L12: 301.11 | M12: 301.11 | N12: 0 | O12: 0 | P12: 601921.89 | Q12: 0 | R12: 1
A13: PF000001 | B13: COMP004 | C13: TR_SYN_0000415 | D13: TRD000004 | E13: 2025-05-30 | F13: 150 | G13: 647.63 | H13: 787 | I13: 509684.81 | J13: 0 | K13: 0 | L13: 254.84 | M13: 254.84 | N13: 0 | O13: 0 | P13: 509429.97 | Q13: 0 | R13: 1
... A240: PF000010 | B240: COMP008 | C240: TR_SYN_0000219 | D240: TRD000002 | E240: 2025-02-28 | F240: 59 | G240: 1223.36 | H240: 786 | I240: 961560.96 | J240: 612835.2 | K240: 306.42 | L240: 480.78 | M240: 787.2 | N240: 780.0784 | O240: 613141.62 | P240: 347938.56 | Q240: 0.56746851 | R240: 1

Sheet fact_splits
A1: company_id | B1: date | C1: split_ratio | D1: calendar_id | E1: exchange_id
A2: COMP004 | B2: 45798 | C2: 1.5 | D2: 141 | E2: EXCH01
A3: COMP008 | B3: 45793 | C3: 2 | D3: 136 | E3: EXCH02
A4: COMP004 | B4: 45821 | C4: 2 | D4: 164 | E4: EXCH01
A5: COMP001 | B5: 45797 | C5: 1.5 | D5: 140 | E5: EXCH01
A6: COMP008 | B6: 45782 | C6: 2 | D6: 125 | E6: EXCH02

Sheet fact_positions_snapshot
A1: portfolio_id | B1: company_id | C1: date | D1: quantity | E1: calendar_id
A2: PF000001 | B2: COMP004 | C2: 45716 | D2: 908 | E2: 59
A3: PF000002 | B3: COMP008 | C3: 45707 | D3: 809 | E3: 50
A4: PF000004 | B4: COMP001 | C4: 45776 | D4: 618 | E4: 119
A5: PF000005 | B5: COMP001 | C5: 45813 | D5: 934 | E5: 156
A6: PF000007 | B6: COMP003 | C6: 45763 | D6: 202 | E6: 106
A7: PF000007 | B7: COMP006 | C7: 45737 | D7: 833 | E7: 80
A8: PF000008 | B8: COMP004 | C8: 45709 | D8: 345 | E8: 52
A9: PF000008 | B9: COMP006 | C9: 45667 | D9: 896 | E9: 10
A10: PF000009 | B10: COMP003 | C10: 45715 | D10: 479 | E10: 58
A11: PF000010 | B11: COMP007 | C11: 45706 | D11: 916 | E11: 49
D12: =SUBTOTAL(109,fact_positions_snapshot[quantity]) -> 6940

Sheet fact_orders
A1: order_id | B1: order_ts | C1: company_id | D1: side | E1: quantity | F1: status | G1: order_type | H1: trader_id | I1: portfolio_id | J1: date | K1: calendar_id | L1: order_ts_imputed | M1: limit_price_imputed | N1: portfolio_id_imputed
A2: ORD00001 | B2: 45713 | C2: COMP002 | D2: BUY | E2: 827 | F2: FILLED | G2: MARKET | H2: TRD000004 | I2: PF000006 | J2: 45716 | K2: 59 | L2: FALSE | M2: TRUE | N2: FALSE
A3: ORD00002 | B3: 45726 | C3: COMP006 | D3: BUY | E3: 665 | F3: FILLED | G3: MARKET | H3: TRD000007 | I3: PF000006 | J3: 45791 | K3: 134 | L3: FALSE | M3: TRUE | N3: FALSE
A4: ORD00003 | B4: 45832 | C4: COMP007 | D4: SELL | E4: 787 | F4: FILLED | G4: MARKET | H4: TRD000020 | I4: PF000006 | J4: 45800 | K4: 143 | L4: FALSE | M4: TRUE | N4: FALSE
A5: ORD00004 | B5: 45687 | C5: COMP002 | D5: BUY | E5: 194 | F5: FILLED | G5: MARKET | H5: TRD000006 | I5: PF000009 | J5: 45805 | K5: 148 | L5: FALSE | M5: TRUE | N5: FALSE
A6: ORD00005 | B6: 45782 | C6: COMP003 | D6: BUY | E6: 331 | F6: FILLED | G6: MARKET | H6: TRD000019 | I6: PF000008 | J6: 45723 | K6: 66 | L6: FALSE | M6: TRUE | N6: FALSE
A7: ORD00006 | B7: 45749 | C7: COMP001 | D7: BUY | E7: 330 | F7: FILLED | G7: MARKET | H7: TRD000012 | I7: PF000006 | J7: 45713 | K7: 56 | L7: FALSE | M7: TRUE | N7: FALSE
A8: ORD00007 | B8: 45765 | C8: COMP006 | D8: BUY | E8: 203 | F8: FILLED | G8: MARKET | H8: TRD000002 | I8: PF000002 | J8: 45819 | K8: 162 | L8: FALSE | M8: TRUE | N8: FALSE
A9: ORD00008 | B9: 45835 | C9: COMP008 | D9: BUY | E9: 323 | F9: FILLED | G9: MARKET | H9: TRD000006 | I9: PF000009 | J9: 45778 | K9: 121 | L9: FALSE | M9: TRUE | N9: FALSE
A10: ORD00009 | B10: 45834 | C10: COMP005 | D10: SELL | E10: 857 | F10: FILLED | G10: MARKET | H10: TRD000016 | I10: PF000002 | J10: 45803 | K10: 146 | L10: FALSE | M10: TRUE | N10: FALSE
A11: ORD00010 | B11: 45803 | C11: COMP008 | D11: BUY | E11: 764 | F11: FILLED | G11: MARKET | H11: TRD000030 | I11: PF000007 | J11: 45758 | K11: 101 | L11: FALSE | M11: TRUE | N11: FALSE
A12: ORD00011 | B12: 45778 | C12: COMP008 | D12: BUY | E12: 151 | F12: FILLED | G12: MARKET | H12: TRD000016 | I12: PF000009 | J12: 45714 | K12: 57 | L12: FALSE | M12: TRUE | N12: FALSE
A13: ORD00012 | B13: 45768 | C13: COMP001 | D13: BUY | E13: 52 | F13: FILLED | G13: MARKET | H13: TRD000015 | I13: PF000002 | J13: 45814 | K13: 157 | L13: FALSE | M13: TRUE | N13: FALSE
... A501: ORD00500 | B501: 45765 | C501: COMP004 | D501: BUY | E501: 902 | F501: FILLED | G501: MARKET | H501: TRD000015 | I501: PF000003 | J501: 45749 | K501: 92 | L501: FALSE | M501: TRUE | N501: FALSE

Sheet fact_dividends
A1: date | B1: company_id | C1: dividend_per_share | D1: calendar_id | E1: exchange_id | F1: is_orphan_dividend
A2: 45747 | B2: COMP003 | C2: 12.5 | D2: 90 | E2: EXCH01 | F2: FALSE
A3: 45747 | B3: COMP006 | C3: 4.37 | D3: 90 | E3: EXCH02 | F3: FALSE
A4: 45747 | B4: COMP007 | C4: 20.39 | D4: 90 | E4: EXCH02 | F4: FALSE
A5: 45838 | B5: COMP001 | C5: 17.05 | D5: 181 | E5: EXCH01 | F5: FALSE
A6: 45838 | B6: COMP002 | C6: 17.6 | D6: 181 | E6: EXCH01 | F6: FALSE
A7: 45838 | B7: COMP006 | C7: 22.35 | D7: 181 | E7: EXCH02 | F7: FALSE
A8: 45838 | B8: COMP007 | C8: 13.49 | D8: 181 | E8: EXCH02 | F8: FALSE
A9: 45838 | B9: COMP008 | C9: 12.25 | D9: 181 | E9: EXCH02 | F9: FALSE

Sheet fact_daily_prices
A1: date | B1: company_id | C1: open | D1: high | E1: low | F1: close | G1: volume | H1: calendar_id | I1: cumulative_factor | J1: adjusted_close | K1: avg_vol | L1: is_volume_suspect | M1: Prev_close | N1: daily Rturn | O1: Eomonth | P1: sector_name
A2: 45658 | B2: COMP001 | C2: 796.56 | D2: 800.79 | E2: 792.33 | F2: 800.53 | G2: 42106 | H2: 1 | I2: 1.5 | J2: 533.68667 | K2: 25295.845 | L2: FALSE | M2: =IF(fact_daily_prices[[#This Row],[company_id]] =$B1,$F1) -> FALSE | N2: =IFERROR(IF(fact_daily_prices[[#This Row],[Prev_close]]="","",((fact_daily_prices[[#This Row],[close]]-fact_daily_prices[[#This Row],[Prev_close]] )/ fact_daily_prices[[#This Row],[Prev_close]])),0) -> 0 | O2: =EOMONTH(fact_daily_prices[[#This Row],[date]],0) -> 45688
A3: 45659 | B3: COMP001 | C3: 805.97 | D3: 809.55 | E3: 802.39 | F3: 803.94 | G3: 9680 | H3: 2 | I3: 1.5 | J3: 535.96 | K3: 25295.845 | L3: FALSE | M3: =IF(fact_daily_prices[[#This Row],[company_id]] =$B2,$F2) -> 800.53 | N3: =IFERROR(IF(fact_daily_prices[[#This Row],[Prev_close]]="","",((fact_daily_prices[[#This Row],[close]]-fact_daily_prices[[#This Row],[Prev_close]] )/ fact_daily_prices[[#This Row],[Prev_close]])),0) -> 0.004259678 | O3: =EOMONTH(fact_daily_prices[[#This Row],[date]],0) -> 45688
A4: 45660 | B4: COMP001 | C4: 809.42 | D4: 818.12 | E4: 800.72 | F4: 806.96 | G4: 36153 | H4: 3 | I4: 1.5 | J4: 537.97333 | K4: 25295.845 | L4: FALSE | M4: =IF(fact_daily_prices[[#This Row],[company_id]] =$B3,$F3) -> 803.94 | N4: =IFERROR(IF(fact_daily_prices[[#This Row],[Prev_close]]="","",((fact_daily_prices[[#This Row],[close]]-fact_daily_prices[[#This Row],[Prev_close]] )/ fact_daily_prices[[#This Row],[Prev_close]])),0) -> 0.0037564992 | O4: =EOMONTH(fact_daily_prices[[#This Row],[date]],0) -> 45688
A5: 45663 | B5: COMP001 | C5: 818.82 | D5: 831.19 | E5: 806.45 | F5: 817.5 | G5: 9120 | H5: 6 | I5: 1.5 | J5: 545 | K5: 25295.845 | L5: FALSE | M5: =IF(fact_daily_prices[[#This Row],[company_id]] =$B4,$F4) -> 806.96 | N5: =IFERROR(IF(fact_daily_prices[[#This Row],[Prev_close]]="","",((fact_daily_prices[[#This Row],[close]]-fact_daily_prices[[#This Row],[Prev_close]] )/ fact_daily_prices[[#This Row],[Prev_close]])),0) -> 0.013061366 | O5: =EOMONTH(fact_daily_prices[[#This Row],[date]],0) -> 45688
A6: 45664 | B6: COMP001 | C6: 805.15 | D6: 813.57 | E6: 796.72 | F6: 811.73 | G6: 21445 | H6: 7 | I6: 1.5 | J6: 541.15333 | K6: 25295.845 | L6: FALSE | M6: =IF(fact_daily_prices[[#This Row],[company_id]] =$B5,$F5) -> 817.5 | N6: =IFERROR(IF(fact_daily_prices[[#This Row],[Prev_close]]="","",((fact_daily_prices[[#This Row],[close]]-fact_daily_prices[[#This Row],[Prev_close]] )/ fact_daily_prices[[#This Row],[Prev_close]])),0) -> -0.007058104 | O6: =EOMONTH(fact_daily_prices[[#This Row],[date]],0) -> 45688
A7: 45665 | B7: COMP001 | C7: 810.34 | D7: 817.79 | E7: 802.88 | F7: 806.57 | G7: 32065 | H7: 8 | I7: 1.5 | J7: 537.71333 | K7: 25295.845 | L7: FALSE | M7: =IF(fact_daily_prices[[#This Row],[company_id]] =$B6,$F6) -> 811.73 | N7: =IFERROR(IF(fact_daily_prices[[#This Row],[Prev_close]]="","",((fact_daily_prices[[#This Row],[close]]-fact_daily_prices[[#This Row],[Prev_close]] )/ fact_daily_prices[[#This Row],[Prev_close]])),0) -> -0.0063567935 | O7: =EOMONTH(fact_daily_prices[[#This Row],[date]],0) -> 45688
A8: 45666 | B8: COMP001 | C8: 804.7 | D8: 816.71 | E8: 792.7 | F8: 800.97 | G8: 46936 | H8: 9 | I8: 1.5 | J8: 533.98 | K8: 25295.845 | L8: FALSE | M8: =IF(fact_daily_prices[[#This Row],[company_id]] =$B7,$F7) -> 806.57 | N8: =IFERROR(IF(fact_daily_prices[[#This Row],[Prev_close]]="","",((fact_daily_prices[[#This Row],[close]]-fact_daily_prices[[#This Row],[Prev_close]] )/ fact_daily_prices[[#This Row],[Prev_close]])),0) -> -0.0069429808 | O8: =EOMONTH(fact_daily_prices[[#This Row],[date]],0) -> 45688
A9: 45667 | B9: COMP001 | C9: 793.07 | D9: 795.72 | E9: 790.42 | F9: 791.89 | G9: 21932 | H9: 10 | I9: 1.5 | J9: 527.92667 | K9: 25295.845 | L9: FALSE | M9: =IF(fact_daily_prices[[#This Row],[company_id]] =$B8,$F8) -> 800.97 | N9: =IFERROR(IF(fact_daily_prices[[#This Row],[Prev_close]]="","",((fact_daily_prices[[#This Row],[close]]-fact_daily_prices[[#This Row],[Prev_close]] )/ fact_daily_prices[[#This Row],[Prev_close]])),0) -> -0.011336255 | O9: =EOMONTH(fact_daily_prices[[#This Row],[date]],0) -> 45688
A10: 45670 | B10: COMP001 | C10: 768.48 | D10: 780.24 | E10: 756.73 | F10: 766.43 | G10: 44016 | H10: 13 | I10: 1.5 | J10: 510.95333 | K10: 25295.845 | L10: FALSE | M10: =IF(fact_daily_prices[[#This Row],[company_id]] =$B9,$F9) -> 791.89 | N10: =IFERROR(IF(fact_daily_prices[[#This Row],[Prev_close]]="","",((fact_daily_prices[[#This Row],[close]]-fact_daily_prices[[#This Row],[Prev_close]] )/ fact_daily_prices[[#This Row],[Prev_close]])),0) -> -0.03215093 | O10: =EOMONTH(fact_daily_prices[[#This Row],[date]],0) -> 45688
A11: 45671 | B11: COMP001 | C11: 772.58 | D11: 780.18 | E11: 764.98 | F11: 775.85 | G11: 2154 | H11: 14 | I11: 1.5 | J11: 517.23333 | K11: 25295.845 | L11: TRUE | M11: =IF(fact_daily_prices[[#This Row],[company_id]] =$B10,$F10) -> 766.43 | N11: =IFERROR(IF(fact_daily_prices[[#This Row],[Prev_close]]="","",((fact_daily_prices[[#This Row],[close]]-fact_daily_prices[[#This Row],[Prev_close]] )/ fact_daily_prices[[#This Row],[Prev_close]])),0) -> 0.012290751 | O11: =EOMONTH(fact_daily_prices[[#This Row],[date]],0) -> 45688
A12: 45672 | B12: COMP001 | C12: 787.6 | D12: 797.49 | E12: 777.72 | F12: 784.06 | G12: 13183 | H12: 15 | I12: 1.5 | J12: 522.70667 | K12: 25295.845 | L12: FALSE | M12: =IF(fact_daily_prices[[#This Row],[company_id]] =$B11,$F11) -> 775.85 | N12: =IFERROR(IF(fact_daily_prices[[#This Row],[Prev_close]]="","",((fact_daily_prices[[#This Row],[close]]-fact_daily_prices[[#This Row],[Prev_close]] )/ fact_daily_prices[[#This Row],[Prev_close]])),0) -> 0.010581942 | O12: =EOMONTH(fact_daily_prices[[#This Row],[date]],0) -> 45688
A13: 45673 | B13: COMP001 | C13: 768.68 | D13: 782.43 | E13: 754.94 | F13: 769.33 | G13: 6539 | H13: 16 | I13: 1.5 | J13: 512.88667 | K13: 25295.845 | L13: FALSE | M13: =IF(fact_daily_prices[[#This Row],[company_id]] =$B12,$F12) -> 784.06 | N13: =IFERROR(IF(fact_daily_prices[[#This Row],[Prev_close]]="","",((fact_daily_prices[[#This Row],[close]]-fact_daily_prices[[#This Row],[Prev_close]] )/ fact_daily_prices[[#This Row],[Prev_close]])),0) -> -0.018786828 | O13: =EOMONTH(fact_daily_prices[[#This Row],[date]],0) -> 45688
... A1033: 45838 | B1033: COMP008 | C1033: 1378.34 | D1033: 1385.28 | E1033: 1371.39 | F1033: 1377.18 | G1033: 24238 | H1033: 181 | I1033: 1 | J1033: 1377.18 | K1033: 24664.891 | L1033: FALSE | M1033: =IF(fact_daily_prices[[#This Row],[company_id]] =$B1032,$F1032) -> 1410.84 | N1033: =IFERROR(IF(fact_daily_prices[[#This Row],[Prev_close]]="","",((fact_daily_prices[[#This Row],[close]]-fact_daily_prices[[#This Row],[Prev_close]] )/ fact_daily_prices[[#This Row],[Prev_close]])),0) -> -0.023858127 | O1033: =EOMONTH(fact_daily_prices[[#This Row],[date]],0) -> 45838
G1034: =SUBTOTAL(109,fact_daily_prices[volume]) -> 26228070

Sheet dim_trader
A1: trader_id | B1: trader_name | C1: desk
A2: TRD000001 | B2: Taylor Shah | C2: Momentum
A3: TRD000002 | B3: Drew Williams | C3: Alpha
A4: TRD000003 | B4: Avery Garcia | C4: Discretionary
A5: TRD000004 | B5: Taylor Harris | C5: Quant
A6: TRD000005 | B6: Jordan Clark | C6: Discretionary
A7: TRD000006 | B7: Reese Patel | C7: Quant
A8: TRD000007 | B8: Alex Lee | C8: Momentum
A9: TRD000008 | B9: Morgan Williams | C9: Quant
A10: TRD000009 | B10: Robin Lewis | C10: Quant
A11: TRD000010 | B11: Alex Harris | C11: Momentum
A12: TRD000011 | B12: Morgan Harris | C12: Quant
... A31: TRD000030 | B31: Riley Lee | C31: Momentum

Sheet dim_sector
A1: sector_id | B1: sector_name
A2: SEC01 | B2: Information Technology
A3: SEC02 | B3: Financials
A4: SEC03 | B4: Healthcare
A5: SEC04 | B5: Energy
A6: SEC05 | B6: Consumer Discretionary

Sheet dim_portfolio
A1: portfolio_id | B1: portfolio_name | C1: manager
A2: PF000001 | B2: Portfolio 1 | C2: Skyler Wilson
A3: PF000002 | B3: Portfolio 2 | C3: Rowan Garcia
A4: PF000003 | B4: Portfolio 3 | C4: Drew Garcia
A5: PF000004 | B5: Portfolio 4 | C5: Avery Harris
A6: PF000005 | B6: Portfolio 5 | C6: Kai Brown
A7: PF000006 | B7: Portfolio 6 | C7: Kendall Anderson
A8: PF000007 | B8: Portfolio 7 | C8: Kendall Wilson
A9: PF000008 | B9: Portfolio 8 | C9: Elliot Williams
A10: PF000009 | B10: Portfolio 9 | C10: Casey White
A11: PF000010 | B11: Portfolio 10 | C11: Skyler Lee

Sheet dim_exchange
A1: exchange_id | B1: exchange_name | C1: country | D1: currency
A2: EXCH01 | B2: NSE | C2: India | D2: INR
A3: EXCH02 | B3: NASDAQ | C3: USA | D3: USD

Sheet dim_company
A1: company_id | B1: ticker | C1: company_name | D1: sector_id | E1: exchange_id
A2: COMP001 | B2: TCS | C2: Tata Consultancy Services | D2: SEC01 | E2: EXCH01
A3: COMP002 | B3: INFY | C3: Infosys | D3: SEC01 | E3: EXCH01
A4: COMP003 | B4: HDFCBANK | C4: HDFC Bank | D4: SEC02 | E4: EXCH01
A5: COMP004 | B5: RELIANCE | C5: Reliance Industries | D5: SEC04 | E5: EXCH01
A6: COMP005 | B6: AAPL | C6: Apple Inc. | D6: SEC01 | E6: EXCH02
A7: COMP006 | B7: MSFT | C7: Microsoft Corp. | D7: SEC01 | E7: EXCH02
A8: COMP007 | B8: AMZN | C8: Amazon.com Inc. | D8: SEC05 | E8: EXCH02
A9: COMP008 | B9: PFE | C9: Pfizer Inc. | D9: SEC03 | E9: EXCH02

Sheet dim_calendar
A1: date | B1: calendar_id | C1: year | D1: month | E1: day | F1: is_month_start | G1: Month_name
A2: 45658 | B2: 1 | C2: 2025 | D2: 1 | E2: 1 | F2: TRUE | G2: =TEXT(dim_calendar[[#This Row],[date]],"MMM") -> Jan
A3: 45659 | B3: 2 | C3: 2025 | D3: 1 | E3: 2 | F3: FALSE | G3: =TEXT(dim_calendar[[#This Row],[date]],"MMM") -> Jan
A4: 45660 | B4: 3 | C4: 2025 | D4: 1 | E4: 3 | F4: FALSE | G4: =TEXT(dim_calendar[[#This Row],[date]],"MMM") -> Jan
A5: 45661 | B5: 4 | C5: 2025 | D5: 1 | E5: 4 | F5: FALSE | G5: =TEXT(dim_calendar[[#This Row],[date]],"MMM") -> Jan
A6: 45662 | B6: 5 | C6: 2025 | D6: 1 | E6: 5 | F6: FALSE | G6: =TEXT(dim_calendar[[#This Row],[date]],"MMM") -> Jan
A7: 45663 | B7: 6 | C7: 2025 | D7: 1 | E7: 6 | F7: FALSE | G7: =TEXT(dim_calendar[[#This Row],[date]],"MMM") -> Jan
A8: 45664 | B8: 7 | C8: 2025 | D8: 1 | E8: 7 | F8: FALSE | G8: =TEXT(dim_calendar[[#This Row],[date]],"MMM") -> Jan
A9: 45665 | B9: 8 | C9: 2025 | D9: 1 | E9: 8 | F9: FALSE | G9: =TEXT(dim_calendar[[#This Row],[date]],"MMM") -> Jan
A10: 45666 | B10: 9 | C10: 2025 | D10: 1 | E10: 9 | F10: FALSE | G10: =TEXT(dim_calendar[[#This Row],[date]],"MMM") -> Jan
A11: 45667 | B11: 10 | C11: 2025 | D11: 1 | E11: 10 | F11: FALSE | G11: =TEXT(dim_calendar[[#This Row],[date]],"MMM") -> Jan
A12: 45668 | B12: 11 | C12: 2025 | D12: 1 | E12: 11 | F12: FALSE | G12: =TEXT(dim_calendar[[#This Row],[date]],"MMM") -> Jan
A13: 45669 | B13: 12 | C13: 2025 | D13: 1 | E13: 12 | F13: FALSE | G13: =TEXT(dim_calendar[[#This Row],[date]],"MMM") -> Jan
... A182: 45838 | B182: 181 | C182: 2025 | D182: 6 | E182: 30 | F182: FALSE | G182: =TEXT(dim_calendar[[#This Row],[date]],"MMM") -> Jun
